[2024-02-11 18:42:07,318] {taskinstance.py:1159} INFO - Dependencies all met for <TaskInstance: sales_mart.upload_user_activity_inc scheduled__2024-02-08T18:36:55.121353+00:00 [queued]>
[2024-02-11 18:42:07,323] {taskinstance.py:1159} INFO - Dependencies all met for <TaskInstance: sales_mart.upload_user_activity_inc scheduled__2024-02-08T18:36:55.121353+00:00 [queued]>
[2024-02-11 18:42:07,323] {taskinstance.py:1356} INFO - 
--------------------------------------------------------------------------------
[2024-02-11 18:42:07,323] {taskinstance.py:1357} INFO - Starting attempt 1 of 1
[2024-02-11 18:42:07,323] {taskinstance.py:1358} INFO - 
--------------------------------------------------------------------------------
[2024-02-11 18:42:07,329] {taskinstance.py:1377} INFO - Executing <Task(PythonOperator): upload_user_activity_inc> on 2024-02-08 18:36:55.121353+00:00
[2024-02-11 18:42:07,332] {standard_task_runner.py:52} INFO - Started process 9913 to run task
[2024-02-11 18:42:07,334] {standard_task_runner.py:79} INFO - Running: ['airflow', 'tasks', 'run', 'sales_mart', 'upload_user_activity_inc', 'scheduled__2024-02-08T18:36:55.121353+00:00', '--job-id', '197', '--raw', '--subdir', 'DAGS_FOLDER/sprint3.py', '--cfg-path', '/tmp/tmpbubepd9b', '--error-file', '/tmp/tmp9suwyewl']
[2024-02-11 18:42:07,334] {standard_task_runner.py:80} INFO - Job 197: Subtask upload_user_activity_inc
[2024-02-11 18:42:07,365] {task_command.py:369} INFO - Running <TaskInstance: sales_mart.upload_user_activity_inc scheduled__2024-02-08T18:36:55.121353+00:00 [running]> on host 2a8d1eb5116f
[2024-02-11 18:42:07,401] {taskinstance.py:1569} INFO - Exporting the following env vars:
AIRFLOW_CTX_DAG_EMAIL=student@example.com
AIRFLOW_CTX_DAG_OWNER=student
AIRFLOW_CTX_DAG_ID=sales_mart
AIRFLOW_CTX_TASK_ID=upload_user_activity_inc
AIRFLOW_CTX_EXECUTION_DATE=2024-02-08T18:36:55.121353+00:00
AIRFLOW_CTX_TRY_NUMBER=1
AIRFLOW_CTX_DAG_RUN_ID=scheduled__2024-02-08T18:36:55.121353+00:00
[2024-02-11 18:42:07,409] {logging_mixin.py:115} INFO - https://storage.yandexcloud.net/s3-sprint3/cohort_22/damir-kalinin7/project/MjAyNC0wMi0wOFQwMDowMDowMAlUV3BCZVU1RE1IZE5hVEI0VFZaUmVFOUViM3BQVkc4eFRWRnNhMWxYTVhCamFURnlXVmQ0Y0dKdGJIVk9kejA5/user_activity_log.csv
[2024-02-11 18:42:07,409] {logging_mixin.py:115} INFO - 20240208_user_activity_log.csv
[2024-02-11 18:42:07,692] {taskinstance.py:1889} ERROR - Task failed with exception
Traceback (most recent call last):
  File "/usr/local/lib/python3.8/dist-packages/airflow/operators/python.py", line 171, in execute
    return_value = self.execute_callable()
  File "/usr/local/lib/python3.8/dist-packages/airflow/operators/python.py", line 189, in execute_callable
    return self.python_callable(*self.op_args, **self.op_kwargs)
  File "/lessons/dags/sprint3.py", line 88, in upload_data_to_staging
    response.raise_for_status()
  File "/usr/local/lib/python3.8/dist-packages/requests/models.py", line 960, in raise_for_status
    raise HTTPError(http_error_msg, response=self)
requests.exceptions.HTTPError: 404 Client Error: Not Found for url: https://storage.yandexcloud.net/s3-sprint3/cohort_22/damir-kalinin7/project/MjAyNC0wMi0wOFQwMDowMDowMAlUV3BCZVU1RE1IZE5hVEI0VFZaUmVFOUViM3BQVkc4eFRWRnNhMWxYTVhCamFURnlXVmQ0Y0dKdGJIVk9kejA5/user_activity_log.csv
[2024-02-11 18:42:07,702] {taskinstance.py:1395} INFO - Marking task as FAILED. dag_id=sales_mart, task_id=upload_user_activity_inc, execution_date=20240208T183655, start_date=20240211T184207, end_date=20240211T184207
[2024-02-11 18:42:07,709] {standard_task_runner.py:92} ERROR - Failed to execute job 197 for task upload_user_activity_inc (404 Client Error: Not Found for url: https://storage.yandexcloud.net/s3-sprint3/cohort_22/damir-kalinin7/project/MjAyNC0wMi0wOFQwMDowMDowMAlUV3BCZVU1RE1IZE5hVEI0VFZaUmVFOUViM3BQVkc4eFRWRnNhMWxYTVhCamFURnlXVmQ0Y0dKdGJIVk9kejA5/user_activity_log.csv; 9913)
[2024-02-11 18:42:07,747] {local_task_job.py:156} INFO - Task exited with return code 1
[2024-02-11 18:42:07,767] {local_task_job.py:273} INFO - 0 downstream tasks scheduled from follow-on schedule check
[2024-02-11 18:42:07,781] {dagrun.py:547} ERROR - Marking run <DagRun sales_mart @ 2024-02-08 18:36:55.121353+00:00: scheduled__2024-02-08T18:36:55.121353+00:00, externally triggered: False> failed
[2024-02-11 18:42:07,781] {dagrun.py:607} INFO - DagRun Finished: dag_id=sales_mart, execution_date=2024-02-08 18:36:55.121353+00:00, run_id=scheduled__2024-02-08T18:36:55.121353+00:00, run_start_date=2024-02-11 18:38:22.284109+00:00, run_end_date=2024-02-11 18:42:07.781764+00:00, run_duration=225.497655, state=failed, external_trigger=False, run_type=scheduled, data_interval_start=2024-02-08 18:36:55.121353+00:00, data_interval_end=2024-02-09 18:36:55.121353+00:00, dag_hash=51dee05362bc5ebf39ec1e12942ad7b7
